const x = 10

try {
    x = 4
} catch(err){

    console.log(`Erro: ${err}`)
}